Feature Extraction
Uncaught exception
Traceback (most recent call last):
  File "c:\Users\39351\Desktop\Multimodal-Egocentric-Action-Recognition-2024\save_feat.py", line 161, in <module>
    main()
  File "c:\Users\39351\Desktop\Multimodal-Egocentric-Action-Recognition-2024\save_feat.py", line 35, in main
    init_operations()
  File "c:\Users\39351\Desktop\Multimodal-Egocentric-Action-Recognition-2024\save_feat.py", line 26, in init_operations
    logger.info("Running with parameters: " + pformat_dict(args, indent=1))
                                              ^^^^^^^^^^^^^^^^^^^^^^^^^^^^
  File "c:\Users\39351\Desktop\Multimodal-Egocentric-Action-Recognition-2024\utils\utils.py", line 119, in pformat_dict
    fstr += pformat_dict(value, indent+1)
            ^^^^^^^^^^^^^^^^^^^^^^^^^^^^^
  File "c:\Users\39351\Desktop\Multimodal-Egocentric-Action-Recognition-2024\utils\utils.py", line 119, in pformat_dict
    fstr += pformat_dict(value, indent+1)
            ^^^^^^^^^^^^^^^^^^^^^^^^^^^^^
  File "c:\Users\39351\Desktop\Multimodal-Egocentric-Action-Recognition-2024\utils\utils.py", line 116, in pformat_dict
    for key, value in d.items():
                      ^^^^^^^^^
  File "C:\Users\39351\anaconda3\Lib\site-packages\omegaconf\dictconfig.py", line 562, in items
    return dict(self.items_ex(resolve=True, keys=None)).items()
                ^^^^^^^^^^^^^^^^^^^^^^^^^^^^^^^^^^^^^^
  File "C:\Users\39351\anaconda3\Lib\site-packages\omegaconf\dictconfig.py", line 588, in items_ex
    value = self[key]
            ~~~~^^^^^
  File "C:\Users\39351\anaconda3\Lib\site-packages\omegaconf\dictconfig.py", line 375, in __getitem__
    self._format_and_raise(key=key, value=None, cause=e)
  File "C:\Users\39351\anaconda3\Lib\site-packages\omegaconf\base.py", line 231, in _format_and_raise
    format_and_raise(
  File "C:\Users\39351\anaconda3\Lib\site-packages\omegaconf\_utils.py", line 899, in format_and_raise
    _raise(ex, cause)
  File "C:\Users\39351\anaconda3\Lib\site-packages\omegaconf\_utils.py", line 797, in _raise
    raise ex.with_traceback(sys.exc_info()[2])  # set env var OC_CAUSE=1 for full trace
    ^^^^^^^^^^^^^^^^^^^^^^^^^^^^^^^^^^^^^^^^^^
  File "C:\Users\39351\anaconda3\Lib\site-packages\omegaconf\dictconfig.py", line 369, in __getitem__
    return self._get_impl(key=key, default_value=_DEFAULT_MARKER_)
           ^^^^^^^^^^^^^^^^^^^^^^^^^^^^^^^^^^^^^^^^^^^^^^^^^^^^^^^
  File "C:\Users\39351\anaconda3\Lib\site-packages\omegaconf\dictconfig.py", line 451, in _get_impl
    return self._resolve_with_default(
           ^^^^^^^^^^^^^^^^^^^^^^^^^^^
  File "C:\Users\39351\anaconda3\Lib\site-packages\omegaconf\basecontainer.py", line 96, in _resolve_with_default
    raise MissingMandatoryValue("Missing mandatory value: $FULL_KEY")
omegaconf.errors.MissingMandatoryValue: Missing mandatory value: dataset.RGB.data_path
    full_key: dataset.RGB.data_path
    object_type=dict
